Rust programming, what's the difference between '?' and '.unwrap()'?

In Rust, `?` and `.unwrap()` are both used for error handling, but they serve different purposes and have different behaviors.

1. `.unwrap()`:
   - `.unwrap()` is a method that is used to extract the value from an `Option` or `Result` type.
   - If the `Option` is `Some(value)` or the `Result` is `Ok(value)`, `.unwrap()` returns the inner `value`.
   - However, if the `Option` is `None` or the `Result` is `Err(error)`, `.unwrap()` will panic and terminate the program.
   - `.unwrap()` should be used when you are absolutely certain that the `Option` or `Result` will always contain a valid value, and you want to extract that value.

2. `?` operator:
   - The `?` operator is used for error propagation in Rust.
   - When used with a `Result` type, if the `Result` is `Ok(value)`, the `?` operator unwraps the value and returns it.
   - If the `Result` is `Err(error)`, the `?` operator propagates the error to the calling function, allowing it to handle the error or continue propagating it up the call stack.
   - The `?` operator can only be used within functions that return a `Result` or an `Option`.
   - It provides a concise way to handle errors and propagate them without explicitly using match expressions or `if let` statements.

Here's an example to illustrate the difference:

```rust
fn main() {
    let result: Result<i32, &str> = Ok(42);
    let value = result.unwrap(); // Unwraps the value, panics if `result` is an `Err`
    println!("Value: {}", value);

    let result: Result<i32, &str> = Err("Something went wrong");
    let value = result?; // Propagates the error, returns from `main` early
    println!("Value: {}", value); // This line is not reached
}
```

In the first case, `.unwrap()` is used to directly extract the value from the `Result`. If `result` is `Ok(42)`, it will print "Value: 42". However, if `result` is an `Err`, `.unwrap()` will panic.

In the second case, the `?` operator is used. If `result` is an `Err`, it will propagate the error and return early from the `main` function. The `println!` statement will not be executed in this case.

It's generally recommended to use the `?` operator for error propagation when working with `Result` types, as it provides a more idiomatic and concise way to handle errors in Rust. `.unwrap()` should be used sparingly and only when you are certain that the value will always be present.


so, for Result<String, Error>, it's same?

Yes, the usage of `?` and `.unwrap()` is the same for `Result<String, Error>` as it is for any other `Result<T, E>` type.

When you have a `Result<String, Error>`:
- If the `Result` is `Ok(string)`, `.unwrap()` will return the inner `String` value.
- If the `Result` is `Err(error)`, `.unwrap()` will panic with the error message.

Similarly, when using the `?` operator with `Result<String, Error>`:
- If the `Result` is `Ok(string)`, the `?` operator will unwrap the `String` value and return it.
- If the `Result` is `Err(error)`, the `?` operator will propagate the `Error` to the calling function.

Here's an example:

```rust
use std::fs::File;
use std::io::Read;

fn read_file_content(file_path: &str) -> Result<String, std::io::Error> {
    let mut file = File::open(file_path)?;
    let mut content = String::new();
    file.read_to_string(&mut content)?;
    Ok(content)
}

fn main() {
    let file_path = "example.txt";
    let content = read_file_content(file_path).unwrap();
    println!("File content: {}", content);
}
```

In this example, the `read_file_content` function returns a `Result<String, std::io::Error>`. It uses the `?` operator to propagate any errors that may occur while opening the file (`File::open(file_path)?`) or reading its content (`file.read_to_string(&mut content)?`). If an error occurs, the `?` operator will return early from the function with the error.

In the `main` function, `.unwrap()` is used to extract the file content from the `Result` returned by `read_file_content`. If the file is read successfully, it will print the content. If an error occurs (e.g., the file doesn't exist), `.unwrap()` will panic with the error message.

Remember to use `.unwrap()` judiciously and only when you are certain that the `Result` will always be `Ok`. In most cases, it's better to use the `?` operator for error propagation or handle the `Result` explicitly using `match` or `if let` statements.


what about other cases that has the same implication ('?' and '.unwrap()' are same).

Certainly! The usage of `?` and `.unwrap()` is similar in other cases where you are working with `Result` or `Option` types. Let's go through a few more examples:

1. `Option<T>`:
   - When you have an `Option<T>`, such as `Option<String>`, you can use `.unwrap()` to extract the value if it is `Some(value)`, or it will panic if it is `None`.
   - The `?` operator can also be used with `Option<T>` in a similar way, but it is typically used in functions that return a `Result`.

Example:
```rust
fn get_first_char(s: &str) -> Option<char> {
    s.chars().next()
}

fn main() {
    let string = "Hello, world!";
    let first_char = get_first_char(string).unwrap();
    println!("First character: {}", first_char);
}
```

2. `Result<(), Error>`:
   - When a function returns a `Result<(), Error>`, it indicates that the function may fail and return an error, but it doesn't produce a meaningful value on success.
   - In this case, you can use `.unwrap()` to ensure that the operation succeeded, or it will panic if an error occurs.
   - The `?` operator can be used to propagate the error if it occurs.

Example:
```rust
use std::fs::create_dir;

fn create_directory(path: &str) -> Result<(), std::io::Error> {
    create_dir(path)?;
    Ok(())
}

fn main() {
    let dir_path = "new_directory";
    create_directory(dir_path).unwrap();
    println!("Directory created successfully!");
}
```

3. `Result<Vec<T>, Error>`:
   - When a function returns a `Result<Vec<T>, Error>`, it indicates that the function may return a vector of values on success or an error on failure.
   - You can use `.unwrap()` to extract the vector if the `Result` is `Ok`, or it will panic if an error occurs.
   - The `?` operator can be used to propagate the error if it occurs.

Example:
```rust
use std::fs::read_dir;

fn get_file_names(dir_path: &str) -> Result<Vec<String>, std::io::Error> {
    let entries = read_dir(dir_path)?;
    let file_names: Vec<String> = entries
        .filter_map(|entry| entry.ok())
        .map(|entry| entry.file_name().to_string_lossy().into_owned())
        .collect();
    Ok(file_names)
}

fn main() {
    let dir_path = "/path/to/directory";
    let file_names = get_file_names(dir_path).unwrap();
    println!("File names: {:?}", file_names);
}
```

In all these cases, `.unwrap()` is used to extract the success value from the `Result` or `Option`, assuming that it will always be `Ok` or `Some`. If the `Result` is an `Err` or the `Option` is `None`, `.unwrap()` will panic.

On the other hand, the `?` operator is used for error propagation. If the `Result` is an `Err`, it will return early from the function and propagate the error to the calling code.

Remember to choose between `?` and `.unwrap()` based on your specific use case and error handling requirements.


I have the following code :

fn main() {
    let unwrap_result: Result<i32, &str> = Ok(42);
    let unwrapped_value = unwrap_result.unwrap(); // Unwraps the value, panics if `result` is an `Err`
    println!("Unwrap Value: {}", unwrapped_value);

    let question_result: Result<i32, &str> = Err("Something went wrong");
    let question_value = question_result?; // Propagates the error, returns from `main` early
    println!("Question Mark Value: {}", question_value); // This line is not reached
}

Why do I get the following error message? :

"""

error[E0277]: the ? operator can only be used in a function that returns Result or Option (or another type that implements FromResidual)

--> code_example_study/examples/result_question_mark_and_unwrap.rs:8:41

|

2 | fn main() {

| --------- this function should return Result or Option to accept ?

...

8 | let question_value = question_result?; // Propagates the error, returns from main early

| ^ cannot use the ? operator in a function that returns ()

|

= help: the trait FromResidual<Result<Infallible, &str>> is not implemented for ()

"""

The error message you're seeing is related to the usage of the `?` operator in the `main` function.

In Rust, the `?` operator is used for error propagation and can only be used within functions that return a `Result` or `Option` (or another type that implements `FromResidual`). The `main` function, by default, has a return type of `()` (unit type), which means it doesn't return any value. Therefore, using the `?` operator directly in the `main` function is not allowed.

To fix this error, you have a few options:

1. Change the return type of the `main` function to `Result<(), &str>` or `Result<(), Box<dyn std::error::Error>>`:

```rust
fn main() -> Result<(), &str> {
    let unwrap_result: Result<i32, &str> = Ok(42);
    let unwrapped_value = unwrap_result.unwrap();
    println!("Unwrap Value: {}", unwrapped_value);

    let question_result: Result<i32, &str> = Err("Something went wrong");
    let question_value = question_result?;
    println!("Question Mark Value: {}", question_value);

    Ok(())
}
```

By changing the return type of `main` to `Result<(), &str>`, you are indicating that the `main` function can return either `Ok(())` (success) or `Err(&str)` (error). This allows the usage of the `?` operator within `main`.

2. Handle the error explicitly using a `match` expression or an `if let` statement:

```rust
fn main() {
    let unwrap_result: Result<i32, &str> = Ok(42);
    let unwrapped_value = unwrap_result.unwrap();
    println!("Unwrap Value: {}", unwrapped_value);

    let question_result: Result<i32, &str> = Err("Something went wrong");
    match question_result {
        Ok(value) => println!("Question Mark Value: {}", value),
        Err(error) => {
            eprintln!("Error: {}", error);
            // Handle the error or return early
        }
    }
}
```

In this approach, instead of using the `?` operator, you explicitly handle the `Result` using a `match` expression. If the `Result` is `Ok`, you can access the value and print it. If it is `Err`, you can handle the error accordingly.

Choose the approach that best fits your needs based on how you want to handle errors in your program.



You stated :

The main function, by default, has a return type of () (unit type)

The last line 'println!("Question Mark Value: {}", question_value);' returned unit or the same line without semicolon yields the same error message. Why having '?' in function cause such error message?


The error message you're seeing is not directly related to the `println!` statement or the semicolon at the end of the line. The error is specifically caused by the usage of the `?` operator in a function that doesn't return a `Result` or `Option`.

Let's break it down:

1. The `?` operator is used for error propagation in Rust. When you use `?` with a `Result` value, it will do one of two things:
   - If the `Result` is `Ok(value)`, the `?` operator will unwrap the value and return it, allowing the execution to continue.
   - If the `Result` is `Err(error)`, the `?` operator will immediately return from the function and propagate the error to the calling code.

2. The `?` operator can only be used within functions that return a `Result` or `Option` (or another type that implements `FromResidual`). This is because the `?` operator needs to know how to propagate the error if it encounters one.

3. In your code, the `main` function has a default return type of `()` (unit type), which means it doesn't return any value. When you use the `?` operator in `main`, Rust doesn't know how to propagate the error because `()` is not a `Result` or `Option`.

The error message is telling you that the `?` operator cannot be used in a function that returns `()`. It suggests that the function should return a `Result` or `Option` to accept the `?` operator.

To resolve the error, you need to either:
- Change the return type of the `main` function to `Result<(), &str>` or `Result<(), Box<dyn std::error::Error>>`, allowing the `?` operator to propagate the error.
- Handle the error explicitly using a `match` expression or an `if let` statement, without using the `?` operator.

Here's an example of changing the return type of `main` to `Result<(), &str>`:

```rust
fn main() -> Result<(), &str> {
    let unwrap_result: Result<i32, &str> = Ok(42);
    let unwrapped_value = unwrap_result.unwrap();
    println!("Unwrap Value: {}", unwrapped_value);

    let question_result: Result<i32, &str> = Err("Something went wrong");
    let question_value = question_result?;
    println!("Question Mark Value: {}", question_value);

    Ok(())
}
```

By changing the return type of `main` to `Result<(), &str>`, the `?` operator is allowed, and the error will be propagated properly. The `main` function now returns `Ok(())` if everything succeeds, or it will return an error of type `&str` if the `?` operator encounters an error.

